<?xml version="1.0" encoding="utf-8"?>
<!-- =================================================================================== -->
<!-- |    This document was autogenerated by xacro from hopping_robot.xacro            | -->
<!-- |    EDITING THIS FILE BY HAND IS NOT RECOMMENDED                                 | -->
<!-- =================================================================================== -->
<!-- Author: Peter Jochem
     Email: peterjochem2020@u.northwestern.edu
     Date: 09/29/2020   -->
<robot name="hopping_robot">
  <link name="torso">
    <visual>
      <geometry>
        <box size="0.4 0.4 0.4"/>
      </geometry>
      <material name="gray">
        <!-- color rgba="255 0 0 0.75" / -->
      </material>
      <origin rpy="0 0 0" xyz="0.0 0.0 0.0"/>
    </visual>
    <inertial>
      <origin rpy="0 0 0" xyz="0.0 0.0 0.0"/>
      <mass value="1.0"/>
      <!-- Fix the inertia tag-->
      <inertia ixx="0.0266666666667" iyy="0.0266666666667" izz="0.0266666666667"/>
    </inertial>
    <collision>
      <origin rpy="0 0 0" xyz="0.0 0.0 0.0"/>
      <geometry>
        <box size="0.4 0.4 0.4"/>
      </geometry>
    </collision>
  </link>
  <link name="leg">
    <visual>
      <geometry>
        <cylinder length="1.0" radius="0.05"/>
      </geometry>
      <material name="gray">
        <!-- color rgba="0 0 255 0.4" / -->
      </material>
      <origin rpy="0 0 0" xyz="0 0 0"/>
    </visual>
    <inertial>
      <origin rpy="0 0 0" xyz="0 0 0"/>
      <mass value="1.0"/>
      <inertia ixx="0.0833333333333" iyy="0.0833333333333" izz="0.0833333333333"/>
    </inertial>
    <collision>
      <origin rpy="0 0 0" xyz="0 0 0"/>
      <geometry>
        <cylinder length="1.0" radius="0.05"/>
      </geometry>
    </collision>
  </link>
  <link name="foot">
    <visual>
      <geometry>
        <box size="0.25 0.6 0.05"/>
      </geometry>
      <material name="gray">
        <!-- color rgba="0 255 0 0.5" / -->
      </material>
      <origin rpy="0 0 0" xyz="0.0 -0.3 0.0"/>
    </visual>
    <inertial>
      <origin rpy="0 0 0" xyz="0.0 -0.3 0.0"/>
      <mass value="1.0"/>
      <!-- Fix the inertia tag-->
      <inertia ixx="0.0302083333333" iyy="0.00541666666667" izz="0.0352083333333"/>
    </inertial>
    <collision>
      <origin rpy="0 0 0" xyz="0.0 -0.3 0.0"/>
      <geometry>
        <box size="0.25 0.6 0.05"/>
      </geometry>
    </collision>
  </link>
  <joint name="torso_leg" type="fixed">
    <parent link="torso"/>
    <child link="leg"/>
    <origin rpy="0 0 0" xyz="0.0 0.0 -0.7"/>
    <axis xyz="0 0 0"/>
  </joint>
  <joint name="leg_foot" type="revolute">
    <origin rpy="0 0 0" xyz="0.0 0.0 -0.525"/>
    <axis xyz="1 0 0"/>
    <parent link="leg"/>
    <child link="foot"/>
    <!-- What to set these to? -->
    <limit effort="10" lower="0.0" upper="1.57" velocity="1.0"/>
  </joint>
  <transmission name="leg_foot_trans" type="transmission_interface/SimpleTransmission">
    <joint name="leg_foot_trans"/>
    <actuator name="leg_foot_trans"/>
    <!-- What to set these to? -->
    <motorInertia>0.0000049</motorInertia>
    <mechanicalReduction>50</mechanicalReduction>
  </transmission>
</robot>

